2024-07-30 11:56:19,683 INFO    StreamThr :14055 [internal.py:wandb_internal():86] W&B internal server running at pid: 14055, started at: 2024-07-30 11:56:19.683277
2024-07-30 11:56:19,684 DEBUG   HandlerThread:14055 [handler.py:handle_request():144] handle_request: status
2024-07-30 11:56:19,689 INFO    WriterThread:14055 [datastore.py:open_for_write():85] open: /Users/mmuhleth/Desktop/diffusion_graph/wandb/run-20240730_115619-jd2p71pm/run-jd2p71pm.wandb
2024-07-30 11:56:19,690 DEBUG   SenderThread:14055 [sender.py:send():369] send: header
2024-07-30 11:56:19,690 DEBUG   SenderThread:14055 [sender.py:send():369] send: run
2024-07-30 11:56:19,961 ERROR   SenderThread:14055 [internal_api.py:execute():323] 404 response executing GraphQL.
2024-07-30 11:56:19,962 ERROR   SenderThread:14055 [internal_api.py:execute():324] {"errors":[{"message":"entity your_username not found during upsertBucket","path":["upsertBucket"]}],"data":{"upsertBucket":null}}
2024-07-30 11:56:19,962 ERROR   SenderThread:14055 [sender.py:send_run():955] It appears that you do not have permission to access the requested resource. Please reach out to the project owner to grant you access. If you have the correct permissions, verify that there are no issues with your networking setup.(Error 404: Not Found)
Traceback (most recent call last):
  File "/opt/anaconda3/envs/digress/lib/python3.9/site-packages/wandb/sdk/lib/retry.py", line 131, in __call__
    result = self._call_fn(*args, **kwargs)
  File "/opt/anaconda3/envs/digress/lib/python3.9/site-packages/wandb/sdk/internal/internal_api.py", line 320, in execute
    return self.client.execute(*args, **kwargs)  # type: ignore
  File "/opt/anaconda3/envs/digress/lib/python3.9/site-packages/wandb/vendor/gql-0.2.0/wandb_gql/client.py", line 52, in execute
    result = self._get_result(document, *args, **kwargs)
  File "/opt/anaconda3/envs/digress/lib/python3.9/site-packages/wandb/vendor/gql-0.2.0/wandb_gql/client.py", line 60, in _get_result
    return self.transport.execute(document, *args, **kwargs)
  File "/opt/anaconda3/envs/digress/lib/python3.9/site-packages/wandb/sdk/lib/gql_request.py", line 56, in execute
    request.raise_for_status()
  File "/opt/anaconda3/envs/digress/lib/python3.9/site-packages/requests/models.py", line 1024, in raise_for_status
    raise HTTPError(http_error_msg, response=self)
requests.exceptions.HTTPError: 404 Client Error: Not Found for url: https://api.wandb.ai/graphql

During handling of the above exception, another exception occurred:

Traceback (most recent call last):
  File "/opt/anaconda3/envs/digress/lib/python3.9/site-packages/wandb/sdk/internal/sender.py", line 953, in send_run
    self._init_run(run, config_value_dict)
  File "/opt/anaconda3/envs/digress/lib/python3.9/site-packages/wandb/sdk/internal/sender.py", line 991, in _init_run
    server_run, inserted, server_messages = self._api.upsert_run(
  File "/opt/anaconda3/envs/digress/lib/python3.9/site-packages/wandb/apis/normalize.py", line 73, in wrapper
    raise err
  File "/opt/anaconda3/envs/digress/lib/python3.9/site-packages/wandb/apis/normalize.py", line 41, in wrapper
    return func(*args, **kwargs)
  File "/opt/anaconda3/envs/digress/lib/python3.9/site-packages/wandb/sdk/internal/internal_api.py", line 1727, in upsert_run
    response = self.gql(
  File "/opt/anaconda3/envs/digress/lib/python3.9/site-packages/wandb/sdk/internal/internal_api.py", line 292, in gql
    ret = self._retry_gql(
  File "/opt/anaconda3/envs/digress/lib/python3.9/site-packages/wandb/sdk/lib/retry.py", line 147, in __call__
    retry_timedelta_triggered = check_retry_fn(e)
  File "/opt/anaconda3/envs/digress/lib/python3.9/site-packages/wandb/util.py", line 908, in check_retry_fn
    return fallback_retry_fn(e)
  File "/opt/anaconda3/envs/digress/lib/python3.9/site-packages/wandb/util.py", line 850, in no_retry_auth
    raise CommError(
wandb.errors.CommError: It appears that you do not have permission to access the requested resource. Please reach out to the project owner to grant you access. If you have the correct permissions, verify that there are no issues with your networking setup.(Error 404: Not Found)
2024-07-30 11:56:20,024 DEBUG   HandlerThread:14055 [handler.py:handle_request():144] handle_request: shutdown
2024-07-30 11:56:20,024 INFO    HandlerThread:14055 [handler.py:finish():854] shutting down handler
2024-07-30 11:56:20,695 INFO    WriterThread:14055 [datastore.py:close():298] close: /Users/mmuhleth/Desktop/diffusion_graph/wandb/run-20240730_115619-jd2p71pm/run-jd2p71pm.wandb
2024-07-30 11:56:20,975 INFO    SenderThread:14055 [sender.py:finish():1526] shutting down sender
