torch.Size([64, 16, 16])
torch.Size([1, 64, 16, 16])
torch.Size([64, 16, 16])
Traceback (most recent call last):
  File "/Users/mmuhleth/Desktop/diffusion_graph/train_ppgn_simple_adj.py", line 104, in <module>
    fit(model, optimizer, dataloader, max_epoch=40, device=device)
  File "/Users/mmuhleth/Desktop/diffusion_graph/train_ppgn_simple_adj.py", line 54, in fit
    score_batch = model(train_noise_adj_b_chunked[i].unsqueeze(0).to(device), train_noise_adj_b_chunked[i].to(device), mask, sigma).to(device)
  File "/opt/anaconda3/envs/digress/lib/python3.9/site-packages/torch/nn/modules/module.py", line 1553, in _wrapped_call_impl
    return self._call_impl(*args, **kwargs)
  File "/opt/anaconda3/envs/digress/lib/python3.9/site-packages/torch/nn/modules/module.py", line 1562, in _call_impl
    return forward_call(*args, **kwargs)
  File "/Users/mmuhleth/Desktop/diffusion_graph/model/model2.py", line 258, in forward
    out = self.forward_cat(A, node_features, mask, noiselevel)
  File "/Users/mmuhleth/Desktop/diffusion_graph/model/model2.py", line 307, in forward_cat
    u = masked_instance_norm2D(u, mask)
  File "/Users/mmuhleth/Desktop/diffusion_graph/util/model_helper.py", line 181, in masked_instance_norm2D
    mask = mask.view(x.size(0), x.size(1), x.size(2), 1).expand_as(x)
RuntimeError: shape '[64, 16, 16, 1]' is invalid for input of size 256
Traceback (most recent call last):
  File "/Users/mmuhleth/Desktop/diffusion_graph/train_ppgn_simple_adj.py", line 104, in <module>
    fit(model, optimizer, dataloader, max_epoch=40, device=device)
  File "/Users/mmuhleth/Desktop/diffusion_graph/train_ppgn_simple_adj.py", line 54, in fit
    score_batch = model(train_noise_adj_b_chunked[i].unsqueeze(0).to(device), train_noise_adj_b_chunked[i].to(device), mask, sigma).to(device)
  File "/opt/anaconda3/envs/digress/lib/python3.9/site-packages/torch/nn/modules/module.py", line 1553, in _wrapped_call_impl
    return self._call_impl(*args, **kwargs)
  File "/opt/anaconda3/envs/digress/lib/python3.9/site-packages/torch/nn/modules/module.py", line 1562, in _call_impl
    return forward_call(*args, **kwargs)
  File "/Users/mmuhleth/Desktop/diffusion_graph/model/model2.py", line 258, in forward
    out = self.forward_cat(A, node_features, mask, noiselevel)
  File "/Users/mmuhleth/Desktop/diffusion_graph/model/model2.py", line 307, in forward_cat
    u = masked_instance_norm2D(u, mask)
  File "/Users/mmuhleth/Desktop/diffusion_graph/util/model_helper.py", line 181, in masked_instance_norm2D
    mask = mask.view(x.size(0), x.size(1), x.size(2), 1).expand_as(x)
RuntimeError: shape '[64, 16, 16, 1]' is invalid for input of size 256